Workbook

Sheet dsa_processed_with_metadata
A1: # | B1: Name | C1: Case ID | D1: Brain Region ID | E1: URL | F1: ID | G1: Year | H1: Done | I1: ABC | J1: Age at Death/Bx | K1: Age at Onset | L1: ApoE | M1: Braak Stage | N1: CERAD | O1: Case Number | P1: Clin Dx | Q1: Cryo Tissue | R1: Duration (years) | S1: Emory Number | T1: Family Hx | U1: Frozen Spinal Cord | V1: Frozen Tissue | W1: Other Neuropathologic Diagnosis - LBD | X1: Other Neuropathologic Diagnosis - Misc 1 | Y1: Other Neuropathologic Diagnosis - TDP | Z1: Other Neuropathologic Diagnosis - Vascular | AA1: PLP/PF Tissue | AB1: PMI (hr) | AC1: Paraffin Blocks | AD1: Primary Neuropathologic Diagnosis | AE1: Race | AF1: Registry or CRIN | AG1: Sex | AH1: Thal | AI1: blockID | AJ1: caseID | AK1: regionName | AL1: regionNameList | AM1: stainID | AN1: verified | AO1: Other Neuropathologic Diagnosis - tau | AP1: Other Neuropathologic Diagnosis - AD | AQ1: Formalin Tissue | AR1: Comments | AS1: fixedId | AT1: offsetX | AU1: offsetY | AV1: rotation | AW1: scaling | AX1: scalingFactor | AY1: size | AZ1: Cause of Death | BA1: Other Neuropathologic Diagnosis - Misc 2 | BB1: antibody | BC1: Clinician | BD1: Dx refined
A2: 1258 | B2: E17-140_1_PTDP.svs | C2: E17-140 | D2: 1 | E2: http://bdsa.pathology.emory.edu:8080/#item/6731690c900c0c0559a4876a | F2: 6731690c900c0c0559a4876a | G2: 2017 | I2: na | J2: 40 | K2: 38 | M2: na | N2: na | O2: E17-140 | P2: ALS | Q2: X | R2: 1.5 | S2: A17-140 | T2: Yes | V2: X | Y2: ALS | AB2: 22 | AD2: FTLD-TDP | AE2: b | AG2: m | AH2: na | AI2: 1 | AJ2: E17-140 | AK2: Hippocampus | AL2: ['Hippocampus'] | AM2: pTDP | AN2: yes | AQ2: X | BD2: ALS
A3: 1259 | B3: E17-140_2_PTDP.svs | C3: E17-140 | D3: 2 | E3: http://bdsa.pathology.emory.edu:8080/#item/673168ea900c0c0559a47fd8 | F3: 673168ea900c0c0559a47fd8 | G3: 2017 | I3: na | J3: 40 | K3: 38 | M3: na | N3: na | O3: E17-140 | P3: ALS | Q3: X | R3: 1.5 | S3: A17-140 | T3: Yes | V3: X | Y3: ALS | AB3: 22 | AD3: FTLD-TDP | AE3: b | AG3: m | AH3: na | AI3: 2 | AJ3: E17-140 | AK3: Amygdala | AL3: ['Amygdala'] | AM3: pTDP | AN3: yes | AQ3: X | BD3: ALS
A4: 1260 | B4: E17-140_3_PTDP.svs | C4: E17-140 | D4: 3 | E4: http://bdsa.pathology.emory.edu:8080/#item/673168f1900c0c0559a4813a | F4: 673168f1900c0c0559a4813a | G4: 2017 | I4: na | J4: 40 | K4: 38 | M4: na | N4: na | O4: E17-140 | P4: ALS | Q4: X | R4: 1.5 | S4: A17-140 | T4: Yes | V4: X | Y4: ALS | AB4: 22 | AD4: FTLD-TDP | AE4: b | AG4: m | AH4: na | AI4: 3 | AJ4: E17-140 | AK4: Frontal Cortex | AL4: ['Frontal cortex'] | AM4: pTDP | AN4: yes | AQ4: X | BD4: ALS
A5: 1261 | B5: E17-140_4_PTDP.svs | C5: E17-140 | D5: 4 | E5: http://bdsa.pathology.emory.edu:8080/#item/673168f7900c0c0559a482c5 | F5: 673168f7900c0c0559a482c5 | G5: 2017 | I5: na | J5: 40 | K5: 38 | M5: na | N5: na | O5: E17-140 | P5: ALS | Q5: X | R5: 1.5 | S5: A17-140 | T5: Yes | V5: X | Y5: ALS | AB5: 22 | AD5: FTLD-TDP | AE5: b | AG5: m | AH5: na | AI5: 4 | AJ5: E17-140 | AK5: Temporal Cortex | AL5: ['Temporal cortex'] | AM5: pTDP | AN5: yes | AQ5: X | BD5: ALS
A6: 1262 | B6: E17-140_5_PTDP.svs | C6: E17-140 | D6: 5 | E6: http://bdsa.pathology.emory.edu:8080/#item/673168ee900c0c0559a4808b | F6: 673168ee900c0c0559a4808b | G6: 2017 | I6: na | J6: 40 | K6: 38 | M6: na | N6: na | O6: E17-140 | P6: ALS | Q6: X | R6: 1.5 | S6: A17-140 | T6: Yes | V6: X | Y6: ALS | AB6: 22 | AD6: FTLD-TDP | AE6: b | AG6: m | AH6: na | AI6: 5 | AJ6: E17-140 | AK6: Parietal Cortex | AL6: ['Parietal cortex'] | AM6: pTDP | AN6: yes | AQ6: X | BD6: ALS
A7: 1263 | B7: E17-140_6_PTDP.svs | C7: E17-140 | D7: 6 | E7: http://bdsa.pathology.emory.edu:8080/#item/67316908900c0c0559a48659 | F7: 67316908900c0c0559a48659 | G7: 2017 | I7: na | J7: 40 | K7: 38 | M7: na | N7: na | O7: E17-140 | P7: ALS | Q7: X | R7: 1.5 | S7: A17-140 | T7: Yes | V7: X | Y7: ALS | AB7: 22 | AD7: FTLD-TDP | AE7: b | AG7: m | AH7: na | AI7: 6 | AJ7: E17-140 | AK7: Occipital Cortex | AL7: ['Occipital cortex'] | AM7: pTDP | AN7: yes | AQ7: X | BD7: ALS
A8: 1264 | B8: E17-140_7_PTDP.svs | C8: E17-140 | D8: 7 | E8: http://bdsa.pathology.emory.edu:8080/#item/67316901900c0c0559a48523 | F8: 67316901900c0c0559a48523 | G8: 2017 | I8: na | J8: 40 | K8: 38 | M8: na | N8: na | O8: E17-140 | P8: ALS | Q8: X | R8: 1.5 | S8: A17-140 | T8: Yes | V8: X | Y8: ALS | AB8: 22 | AD8: FTLD-TDP | AE8: b | AG8: m | AH8: na | AI8: 7 | AJ8: E17-140 | AK8: Peri-Rolandic Cortex, left | AL8: ['Left perirolandic cortex'] | AM8: pTDP | AN8: yes | AQ8: X | BD8: ALS
A9: 1265 | B9: E17-140_10_PTDP.svs | C9: E17-140 | D9: 10 | E9: http://bdsa.pathology.emory.edu:8080/#item/673168f2900c0c0559a4815b | F9: 673168f2900c0c0559a4815b | G9: 2017 | I9: na | J9: 40 | K9: 38 | M9: na | N9: na | O9: E17-140 | P9: ALS | Q9: X | R9: 1.5 | S9: A17-140 | T9: Yes | V9: X | Y9: ALS | AB9: 22 | AD9: FTLD-TDP | AE9: b | AG9: m | AH9: na | AI9: 10 | AJ9: E17-140 | AK9: Basal Ganglia/Nucleus Baysalis | AL9: ['Basal ganglia, Nucleus Baysalis'] | AM9: pTDP | AN9: yes | AQ9: X | BD9: ALS
A10: 1266 | B10: E17-140_11_PTDP.svs | C10: E17-140 | D10: 11 | E10: http://bdsa.pathology.emory.edu:8080/#item/673168eb900c0c0559a48017 | F10: 673168eb900c0c0559a48017 | G10: 2017 | I10: na | J10: 40 | K10: 38 | M10: na | N10: na | O10: E17-140 | P10: ALS | Q10: X | R10: 1.5 | S10: A17-140 | T10: Yes | V10: X | Y10: ALS | AB10: 22 | AD10: FTLD-TDP | AE10: b | AG10: m | AH10: na | AI10: 11 | AJ10: E17-140 | AK10: Basal Ganglia | AL10: ['Basal ganglia'] | AM10: pTDP | AN10: yes | AQ10: X | BD10: ALS
A11: 1267 | B11: E17-140_16_PTDP.svs | C11: E17-140 | D11: 16 | E11: http://bdsa.pathology.emory.edu:8080/#item/673168ef900c0c0559a480ca | F11: 673168ef900c0c0559a480ca | G11: 2017 | I11: na | J11: 40 | K11: 38 | M11: na | N11: na | O11: E17-140 | P11: ALS | Q11: X | R11: 1.5 | S11: A17-140 | T11: Yes | V11: X | Y11: ALS | AB11: 22 | AD11: FTLD-TDP | AE11: b | AG11: m | AH11: na | AI11: 16 | AJ11: E17-140 | AK11: Medulla | AL11: ['Medulla'] | AM11: pTDP | AN11: yes | AQ11: X | BD11: ALS
A12: 1268 | B12: E17-140_17_PTDP.svs | C12: E17-140 | D12: 17 | E12: http://bdsa.pathology.emory.edu:8080/#item/673168f8900c0c0559a482ff | F12: 673168f8900c0c0559a482ff | G12: 2017 | I12: na | J12: 40 | K12: 38 | M12: na | N12: na | O12: E17-140 | P12: ALS | Q12: X | R12: 1.5 | S12: A17-140 | T12: Yes | V12: X | Y12: ALS | AB12: 22 | AD12: FTLD-TDP | AE12: b | AG12: m | AH12: na | AI12: 17 | AJ12: E17-140 | AK12: Cerebellum | AL12: ['Cerebellum'] | AM12: pTDP | AN12: yes | AQ12: X | BD12: ALS
A13: 1269 | B13: E17-140_18_PTDP.svs | C13: E17-140 | D13: 18 | E13: http://bdsa.pathology.emory.edu:8080/#item/673168f9900c0c0559a4833c | F13: 673168f9900c0c0559a4833c | G13: 2017 | I13: na | J13: 40 | K13: 38 | M13: na | N13: na | O13: E17-140 | P13: ALS | Q13: X | R13: 1.5 | S13: A17-140 | T13: Yes | V13: X | Y13: ALS | AB13: 22 | AD13: FTLD-TDP | AE13: b | AG13: m | AH13: na | AI13: 18 | AJ13: E17-140 | AK13: Spinal Cord, upper | AL13: ['Upper spinal cord'] | AM13: pTDP | AN13: yes | AQ13: X | BD13: ALS
... A15: 1271 | B15: E17-140_20_PTDP.svs | C15: E17-140 | D15: 20 | E15: http://bdsa.pathology.emory.edu:8080/#item/673168f5900c0c0559a48251 | F15: 673168f5900c0c0559a48251 | G15: 2017 | I15: na | J15: 40 | K15: 38 | M15: na | N15: na | O15: E17-140 | P15: ALS | Q15: X | R15: 1.5 | S15: A17-140 | T15: Yes | V15: X | Y15: ALS | AB15: 22 | AD15: FTLD-TDP | AE15: b | AG15: m | AH15: na | AI15: 20 | AJ15: E17-140 | AK15: Spinal Cord, lower | AL15: ['Lower spinal cord'] | AM15: pTDP | AN15: yes | AQ15: X | BD15: ALS
A16: 1832 | B16: A15-30_23_pTDP.svs | C16: E/A15-30 | D16: 23 | E16: http://bdsa.pathology.emory.edu:8080/#item/67318553900c0c0559ab2e5a | F16: 67318553900c0c0559ab2e5a | G16: 2015 | I16: 0 | J16: 66 | K16: 62 | L16: E4/4 | M16: II | N16: 0 | O16: E15-30 | P16: FTD; ALS | Q16: X | R16: 4 | S16: A15-30 | T16: Yes | U16: X | V16: X | Y16: ALS | AA16: X | AB16: 7 | AC16: X | AD16: FTLD-TDP (C9 expansion) | AE16: w | AF16: Honor | AG16: m | AH16: 0 | AI16: 23 | AJ16: E15-30 | AK16: Ventral roots | AL16: ['Ventral roots'] | AM16: pTDP | AN16: yes | AO16: PART | BD16: FTD; ALS
A17: 1833 | B17: A15-30_24_pTDP.svs | C17: E/A15-30 | D17: 24 | E17: http://bdsa.pathology.emory.edu:8080/#item/6731855c900c0c0559ab3065 | F17: 6731855c900c0c0559ab3065 | G17: 2015 | I17: 0 | J17: 66 | K17: 62 | L17: E4/4 | M17: II | N17: 0 | O17: E15-30 | P17: FTD; ALS | Q17: X | R17: 4 | S17: A15-30 | T17: Yes | U17: X | V17: X | Y17: ALS | AA17: X | AB17: 7 | AC17: X | AD17: FTLD-TDP (C9 expansion) | AE17: w | AF17: Honor | AG17: m | AH17: 0 | AI17: 24 | AJ17: E15-30 | AK17: Dorsal root ganglia | AL17: ['Dorsal root ganglia'] | AM17: pTDP | AN17: yes | AO17: PART | BD17: FTD; ALS
A18: 1834 | B18: E15-30_2_pTDP.svs | C18: E15-30 | D18: 2 | E18: http://bdsa.pathology.emory.edu:8080/#item/67318587900c0c0559ab3ba9 | F18: 67318587900c0c0559ab3ba9 | G18: 2015 | I18: 0 | J18: 66 | K18: 62 | L18: E4/4 | M18: II | N18: 0 | O18: E15-30 | P18: FTD; ALS | Q18: X | R18: 4 | S18: A15-30 | T18: Yes | U18: X | V18: X | Y18: ALS | AA18: X | AB18: 7 | AC18: X | AD18: FTLD-TDP (C9 expansion) | AE18: w | AF18: Honor | AG18: m | AH18: 0 | AI18: 2 | AJ18: E15-30 | AK18: Amygdala | AL18: ['Amygdala'] | AM18: pTDP | AN18: yes | AO18: PART | BD18: FTD; ALS
A19: 1835 | B19: E15-30_3_pTDP.svs | C19: E15-30 | D19: 3 | E19: http://bdsa.pathology.emory.edu:8080/#item/67318578900c0c0559ab3867 | F19: 67318578900c0c0559ab3867 | G19: 2015 | I19: 0 | J19: 66 | K19: 62 | L19: E4/4 | M19: II | N19: 0 | O19: E15-30 | P19: FTD; ALS | Q19: X | R19: 4 | S19: A15-30 | T19: Yes | U19: X | V19: X | Y19: ALS | AA19: X | AB19: 7 | AC19: X | AD19: FTLD-TDP (C9 expansion) | AE19: w | AF19: Honor | AG19: m | AH19: 0 | AI19: 3 | AJ19: E15-30 | AK19: Frontal cortex with small infarct | AL19: ['Frontal cortex with small infarct'] | AM19: pTDP | AN19: yes | AO19: PART | BD19: FTD; ALS
A20: 1836 | B20: E15-30_4_pTDP.svs | C20: E15-30 | D20: 4 | E20: http://bdsa.pathology.emory.edu:8080/#item/67318568900c0c0559ab3429 | F20: 67318568900c0c0559ab3429 | G20: 2015 | I20: 0 | J20: 66 | K20: 62 | L20: E4/4 | M20: II | N20: 0 | O20: E15-30 | P20: FTD; ALS | Q20: X | R20: 4 | S20: A15-30 | T20: Yes | U20: X | V20: X | Y20: ALS | AA20: X | AB20: 7 | AC20: X | AD20: FTLD-TDP (C9 expansion) | AE20: w | AF20: Honor | AG20: m | AH20: 0 | AI20: 4 | AJ20: E15-30 | AK20: Temporal cortex with infarct | AL20: ['Temporal cortex with small infarct'] | AM20: pTDP | AN20: yes | AO20: PART | BD20: FTD; ALS
A21: 1837 | B21: E15-30_5_pTDP.svs | C21: E15-30 | D21: 5 | E21: http://bdsa.pathology.emory.edu:8080/#item/67318578900c0c0559ab38ba | F21: 67318578900c0c0559ab38ba | G21: 2015 | I21: 0 | J21: 66 | K21: 62 | L21: E4/4 | M21: II | N21: 0 | O21: E15-30 | P21: FTD; ALS | Q21: X | R21: 4 | S21: A15-30 | T21: Yes | U21: X | V21: X | Y21: ALS | AA21: X | AB21: 7 | AC21: X | AD21: FTLD-TDP (C9 expansion) | AE21: w | AF21: Honor | AG21: m | AH21: 0 | AI21: 5 | AJ21: E15-30 | AK21: Parietal cortex | AL21: ['Parietal cortex'] | AM21: pTDP | AN21: yes | AO21: PART | BD21: FTD; ALS
A22: 1838 | B22: E15-30_6_pTDP.svs | C22: E15-30 | D22: 6 | E22: http://bdsa.pathology.emory.edu:8080/#item/67318549900c0c0559ab2c4b | F22: 67318549900c0c0559ab2c4b | G22: 2015 | I22: 0 | J22: 66 | K22: 62 | L22: E4/4 | M22: II | N22: 0 | O22: E15-30 | P22: FTD; ALS | Q22: X | R22: 4 | S22: A15-30 | T22: Yes | U22: X | V22: X | Y22: ALS | AA22: X | AB22: 7 | AC22: X | AD22: FTLD-TDP (C9 expansion) | AE22: w | AF22: Honor | AG22: m | AH22: 0 | AI22: 6 | AJ22: E15-30 | AK22: Occipital cortex | AL22: ['Occipital cortex'] | AM22: pTDP | AN22: yes | AO22: PART | BD22: FTD; ALS
A23: 1839 | B23: E15-30_7_pTDP.svs | C23: E15-30 | D23: 7 | E23: http://bdsa.pathology.emory.edu:8080/#item/6731855b900c0c0559ab2fce | F23: 6731855b900c0c0559ab2fce | G23: 2015 | I23: 0 | J23: 66 | K23: 62 | L23: E4/4 | M23: II | N23: 0 | O23: E15-30 | P23: FTD; ALS | Q23: X | R23: 4 | S23: A15-30 | T23: Yes | U23: X | V23: X | Y23: ALS | AA23: X | AB23: 7 | AC23: X | AD23: FTLD-TDP (C9 expansion) | AE23: w | AF23: Honor | AG23: m | AH23: 0 | AI23: 7 | AJ23: E15-30 | AK23: Left peri-Rolandic cortex | AL23: ['Left perirolandic cortex'] | AM23: pTDP | AN23: yes | AO23: PART | BD23: FTD; ALS
A24: 1840 | B24: E15-30_8_pTDP.svs | C24: E15-30 | D24: 8 | E24: http://bdsa.pathology.emory.edu:8080/#item/67318558900c0c0559ab2f3e | F24: 67318558900c0c0559ab2f3e | G24: 2015 | I24: 0 | J24: 66 | K24: 62 | L24: E4/4 | M24: II | N24: 0 | O24: E15-30 | P24: FTD; ALS | Q24: X | R24: 4 | S24: A15-30 | T24: Yes | U24: X | V24: X | Y24: ALS | AA24: X | AB24: 7 | AC24: X | AD24: FTLD-TDP (C9 expansion) | AE24: w | AF24: Honor | AG24: m | AH24: 0 | AI24: 8 | AJ24: E15-30 | AK24: Right peri-Rolandic cortex | AL24: ['Right perirolandic cortex'] | AM24: pTDP | AN24: yes | AO24: PART | BD24: FTD; ALS
A25: 1841 | B25: E15-30_10_pTDP.svs | C25: E15-30 | D25: 10 | E25: http://bdsa.pathology.emory.edu:8080/#item/67318583900c0c0559ab3b02 | F25: 67318583900c0c0559ab3b02 | G25: 2015 | I25: 0 | J25: 66 | K25: 62 | L25: E4/4 | M25: II | N25: 0 | O25: E15-30 | P25: FTD; ALS | Q25: X | R25: 4 | S25: A15-30 | T25: Yes | U25: X | V25: X | Y25: ALS | AA25: X | AB25: 7 | AC25: X | AD25: FTLD-TDP (C9 expansion) | AE25: w | AF25: Honor | AG25: m | AH25: 0 | AI25: 10 | AJ25: E15-30 | AK25: Insular cortex | AL25: ['Insular cortex'] | AM25: pTDP | AN25: yes | AO25: PART | BD25: FTD; ALS
A26: 1842 | B26: E15-30_11_pTDP.svs | C26: E15-30 | D26: 11 | E26: http://bdsa.pathology.emory.edu:8080/#item/67318572900c0c0559ab36e0 | F26: 67318572900c0c0559ab36e0 | G26: 2015 | I26: 0 | J26: 66 | K26: 62 | L26: E4/4 | M26: II | N26: 0 | O26: E15-30 | P26: FTD; ALS | Q26: X | R26: 4 | S26: A15-30 | T26: Yes | U26: X | V26: X | Y26: ALS | AA26: X | AB26: 7 | AC26: X | AD26: FTLD-TDP (C9 expansion) | AE26: w | AF26: Honor | AG26: m | AH26: 0 | AI26: 11 | AJ26: E15-30 | AK26: Anterior basal ganglia | AL26: ['Anterior basal ganglia'] | AM26: pTDP | AN26: yes | AO26: PART | BD26: FTD; ALS
A27: 1843 | B27: E15-30_12_pTDP.svs | C27: E15-30 | D27: 12 | E27: http://bdsa.pathology.emory.edu:8080/#item/6731854d900c0c0559ab2d56 | F27: 6731854d900c0c0559ab2d56 | G27: 2015 | I27: 0 | J27: 66 | K27: 62 | L27: E4/4 | M27: II | N27: 0 | O27: E15-30 | P27: FTD; ALS | Q27: X | R27: 4 | S27: A15-30 | T27: Yes | U27: X | V27: X | Y27: ALS | AA27: X | AB27: 7 | AC27: X | AD27: FTLD-TDP (C9 expansion) | AE27: w | AF27: Honor | AG27: m | AH27: 0 | AI27: 12 | AJ27: E15-30 | AK27: Posterior basal ganglia | AL27: ['Posterior basal ganglia'] | AM27: pTDP | AN27: yes | AO27: PART | BD27: FTD; ALS
... A36: 1852 | B36: E15-30_22_pTDP.svs | C36: E15-30 | D36: 22 | E36: http://bdsa.pathology.emory.edu:8080/#item/67318555900c0c0559ab2ed5 | F36: 67318555900c0c0559ab2ed5 | G36: 2015 | I36: 0 | J36: 66 | K36: 62 | L36: E4/4 | M36: II | N36: 0 | O36: E15-30 | P36: FTD; ALS | Q36: X | R36: 4 | S36: A15-30 | T36: Yes | U36: X | V36: X | Y36: ALS | AA36: X | AB36: 7 | AC36: X | AD36: FTLD-TDP (C9 expansion) | AE36: w | AF36: Honor | AG36: m | AH36: 0 | AI36: 22 | AJ36: E15-30 | AK36: Dorsal roots | AL36: ['Dorsal roots'] | AM36: pTDP | AN36: yes | AO36: PART | BD36: FTD; ALS
A37: 1875 | B37: E15-46_2_pTDP.svs | C37: E15-46 | D37: 2 | E37: http://bdsa.pathology.emory.edu:8080/#item/673181d3900c0c0559aa5af6 | F37: 673181d3900c0c0559aa5af6 | G37: 2015 | I37: na | J37: 67 | K37: 58 | M37: na | N37: 0 | O37: E15-46 | P37: FTD; ALS | Q37: X | R37: 9 | S37: A15-46 | T37: Yes | U37: X | V37: X | Y37: ALS | AA37: X | AB37: 4 | AC37: X | AD37: FTLD-TDP (C9 expansion) | AE37: w | AG37: m | AH37: 2 | AI37: 2 | AJ37: E15-46 | AK37: Amygdala | AL37: ['Amygdala'] | AM37: pTDP | AN37: yes | AO37: Tau pathology-mild | AR37: sister = E23-119 | BD37: FTD; ALS
A38: 1876 | B38: E15-46_3_pTDP.svs | C38: E15-46 | D38: 3 | E38: http://bdsa.pathology.emory.edu:8080/#item/673181ed900c0c0559aa61d8 | F38: 673181ed900c0c0559aa61d8 | G38: 2015 | I38: na | J38: 67 | K38: 58 | M38: na | N38: 0 | O38: E15-46 | P38: FTD; ALS | Q38: X | R38: 9 | S38: A15-46 | T38: Yes | U38: X | V38: X | Y38: ALS | AA38: X | AB38: 4 | AC38: X | AD38: FTLD-TDP (C9 expansion) | AE38: w | AG38: m | AH38: 2 | AI38: 3 | AJ38: E15-46 | AK38: Frontal cortex with small infarct | AL38: ['Frontal cortex with small infarct'] | AM38: pTDP | AN38: yes | AO38: Tau pathology-mild | AR38: sister = E23-119 | BD38: FTD; ALS
A39: 1877 | B39: E15-46_4_pTDP.svs | C39: E15-46 | D39: 4 | E39: http://bdsa.pathology.emory.edu:8080/#item/673181dd900c0c0559aa5db9 | F39: 673181dd900c0c0559aa5db9 | G39: 2015 | I39: na | J39: 67 | K39: 58 | M39: na | N39: 0 | O39: E15-46 | P39: FTD; ALS | Q39: X | R39: 9 | S39: A15-46 | T39: Yes | U39: X | V39: X | Y39: ALS | AA39: X | AB39: 4 | AC39: X | AD39: FTLD-TDP (C9 expansion) | AE39: w | AG39: m | AH39: 2 | AI39: 4 | AJ39: E15-46 | AK39: Temporal cortex with infarct | AL39: ['Temporal cortex with small infarct'] | AM39: pTDP | AN39: yes | AO39: Tau pathology-mild | AR39: sister = E23-119 | BD39: FTD; ALS
A40: 1878 | B40: E15-46_5_pTDP.svs | C40: E15-46 | D40: 5 | E40: http://bdsa.pathology.emory.edu:8080/#item/673181c0900c0c0559aa569c | F40: 673181c0900c0c0559aa569c | G40: 2015 | I40: na | J40: 67 | K40: 58 | M40: na | N40: 0 | O40: E15-46 | P40: FTD; ALS | Q40: X | R40: 9 | S40: A15-46 | T40: Yes | U40: X | V40: X | Y40: ALS | AA40: X | AB40: 4 | AC40: X | AD40: FTLD-TDP (C9 expansion) | AE40: w | AG40: m | AH40: 2 | AI40: 5 | AJ40: E15-46 | AK40: Parietal cortex | AL40: ['Parietal cortex'] | AM40: pTDP | AN40: yes | AO40: Tau pathology-mild | AR40: sister = E23-119 | BD40: FTD; ALS
A41: 1879 | B41: E15-46_6_pTDP.svs | C41: E15-46 | D41: 6 | E41: http://bdsa.pathology.emory.edu:8080/#item/673181bc900c0c0559aa55e3 | F41: 673181bc900c0c0559aa55e3 | G41: 2015 | I41: na | J41: 67 | K41: 58 | M41: na | N41: 0 | O41: E15-46 | P41: FTD; ALS | Q41: X | R41: 9 | S41: A15-46 | T41: Yes | U41: X | V41: X | Y41: ALS | AA41: X | AB41: 4 | AC41: X | AD41: FTLD-TDP (C9 expansion) | AE41: w | AG41: m | AH41: 2 | AI41: 6 | AJ41: E15-46 | AK41: Occipital cortex | AL41: ['Occipital cortex'] | AM41: pTDP | AN41: yes | AO41: Tau pathology-mild | AR41: sister = E23-119 | BD41: FTD; ALS
A42: 1880 | B42: E15-46_7_pTDP.svs | C42: E15-46 | D42: 7 | E42: http://bdsa.pathology.emory.edu:8080/#item/6731819d900c0c0559aa4eea | F42: 6731819d900c0c0559aa4eea | G42: 2015 | I42: na | J42: 67 | K42: 58 | M42: na | N42: 0 | O42: E15-46 | P42: FTD; ALS | Q42: X | R42: 9 | S42: A15-46 | T42: Yes | U42: X | V42: X | Y42: ALS | AA42: X | AB42: 4 | AC42: X | AD42: FTLD-TDP (C9 expansion) | AE42: w | AG42: m | AH42: 2 | AI42: 7 | AJ42: E15-46 | AK42: Left peri-Rolandic cortex | AL42: ['Left perirolandic cortex'] | AM42: pTDP | AN42: yes | AO42: Tau pathology-mild | AR42: sister = E23-119 | BD42: FTD; ALS
A43: 1881 | B43: E15-46_8_pTDP.svs | C43: E15-46 | D43: 8 | E43: http://bdsa.pathology.emory.edu:8080/#item/6731819d900c0c0559aa4ea7 | F43: 6731819d900c0c0559aa4ea7 | G43: 2015 | I43: na | J43: 67 | K43: 58 | M43: na | N43: 0 | O43: E15-46 | P43: FTD; ALS | Q43: X | R43: 9 | S43: A15-46 | T43: Yes | U43: X | V43: X | Y43: ALS | AA43: X | AB43: 4 | AC43: X | AD43: FTLD-TDP (C9 expansion) | AE43: w | AG43: m | AH43: 2 | AI43: 8 | AJ43: E15-46 | AK43: Right peri-Rolandic cortex | AL43: ['Right perirolandic cortex'] | AM43: pTDP | AN43: yes | AO43: Tau pathology-mild | AR43: sister = E23-119 | BD43: FTD; ALS
A44: 1882 | B44: E15-46_10_pTDP.svs | C44: E15-46 | D44: 10 | E44: http://bdsa.pathology.emory.edu:8080/#item/67318198900c0c0559aa4dbe | F44: 67318198900c0c0559aa4dbe | G44: 2015 | I44: na | J44: 67 | K44: 58 | M44: na | N44: 0 | O44: E15-46 | P44: FTD; ALS | Q44: X | R44: 9 | S44: A15-46 | T44: Yes | U44: X | V44: X | Y44: ALS | AA44: X | AB44: 4 | AC44: X | AD44: FTLD-TDP (C9 expansion) | AE44: w | AG44: m | AH44: 2 | AI44: 10 | AJ44: E15-46 | AK44: Insular cortex | AL44: ['Insular cortex'] | AM44: pTDP | AN44: yes | AO44: Tau pathology-mild | AR44: sister = E23-119 | BD44: FTD; ALS
A45: 1883 | B45: E15-46_11_pTDP.svs | C45: E15-46 | D45: 11 | E45: http://bdsa.pathology.emory.edu:8080/#item/673181aa900c0c0559aa5185 | F45: 673181aa900c0c0559aa5185 | G45: 2015 | I45: na | J45: 67 | K45: 58 | M45: na | N45: 0 | O45: E15-46 | P45: FTD; ALS | Q45: X | R45: 9 | S45: A15-46 | T45: Yes | U45: X | V45: X | Y45: ALS | AA45: X | AB45: 4 | AC45: X | AD45: FTLD-TDP (C9 expansion) | AE45: w | AG45: m | AH45: 2 | AI45: 11 | AJ45: E15-46 | AK45: Anterior basal ganglia | AL45: ['Anterior basal ganglia'] | AM45: pTDP | AN45: yes | AO45: Tau pathology-mild | AR45: sister = E23-119 | BD45: FTD; ALS
A46: 1884 | B46: E15-46_12_pTDP.svs | C46: E15-46 | D46: 12 | E46: http://bdsa.pathology.emory.edu:8080/#item/673181d5900c0c0559aa5b4b | F46: 673181d5900c0c0559aa5b4b | G46: 2015 | I46: na | J46: 67 | K46: 58 | M46: na | N46: 0 | O46: E15-46 | P46: FTD; ALS | Q46: X | R46: 9 | S46: A15-46 | T46: Yes | U46: X | V46: X | Y46: ALS | AA46: X | AB46: 4 | AC46: X | AD46: FTLD-TDP (C9 expansion) | AE46: w | AG46: m | AH46: 2 | AI46: 12 | AJ46: E15-46 | AK46: Posterior basal ganglia | AL46: ['Posterior basal ganglia'] | AM46: pTDP | AN46: yes | AO46: Tau pathology-mild | AR46: sister = E23-119 | BD46: FTD; ALS
A47: 1885 | B47: E15-46_13_pTDP.svs | C47: E15-46 | D47: 13 | E47: http://bdsa.pathology.emory.edu:8080/#item/673181e1900c0c0559aa5eed | F47: 673181e1900c0c0559aa5eed | G47: 2015 | I47: na | J47: 67 | K47: 58 | M47: na | N47: 0 | O47: E15-46 | P47: FTD; ALS | Q47: X | R47: 9 | S47: A15-46 | T47: Yes | U47: X | V47: X | Y47: ALS | AA47: X | AB47: 4 | AC47: X | AD47: FTLD-TDP (C9 expansion) | AE47: w | AG47: m | AH47: 2 | AI47: 13 | AJ47: E15-46 | AK47: Hypothalamus | AL47: ['Hypothalamus'] | AM47: pTDP | AN47: yes | AO47: Tau pathology-mild | AR47: sister = E23-119 | BD47: FTD; ALS
A48: 1886 | B48: E15-46_14_pTDP.svs | C48: E15-46 | D48: 14 | E48: http://bdsa.pathology.emory.edu:8080/#item/673181d8900c0c0559aa5c66 | F48: 673181d8900c0c0559aa5c66 | G48: 2015 | I48: na | J48: 67 | K48: 58 | M48: na | N48: 0 | O48: E15-46 | P48: FTD; ALS | Q48: X | R48: 9 | S48: A15-46 | T48: Yes | U48: X | V48: X | Y48: ALS | AA48: X | AB48: 4 | AC48: X | AD48: FTLD-TDP (C9 expansion) | AE48: w | AG48: m | AH48: 2 | AI48: 14 | AJ48: E15-46 | AK48: Thalamus | AL48: ['Thalamus'] | AM48: pTDP | AN48: yes | AO48: Tau pathology-mild | AR48: sister = E23-119 | BD48: FTD; ALS
... A56: 1894 | B56: E15-46_23_pTDP.svs | C56: E15-46 | D56: 23 | E56: http://bdsa.pathology.emory.edu:8080/#item/673181e6900c0c0559aa606c | F56: 673181e6900c0c0559aa606c | G56: 2015 | I56: na | J56: 67 | K56: 58 | M56: na | N56: 0 | O56: E15-46 | P56: FTD; ALS | Q56: X | R56: 9 | S56: A15-46 | T56: Yes | U56: X | V56: X | Y56: ALS | AA56: X | AB56: 4 | AC56: X | AD56: FTLD-TDP (C9 expansion) | AE56: w | AG56: m | AH56: 2 | AI56: 23 | AJ56: E15-46 | AK56: Dorsal root ganglia | AL56: ['Dorsal root ganglia'] | AM56: pTDP | AN56: yes | AO56: Tau pathology-mild | AR56: sister = E23-119 | BD56: FTD; ALS
...

Sheet Sheet5

Sheet Sheet1
A1: =dsa_processed_with_metadata!J1 -> Age at Death/Bx | B1: Braak Stage | C1: =dsa_processed_with_metadata!M1 -> Braak Stage
A2: =dsa_processed_with_metadata!J588 -> 78 | B2: =SUBSTITUTE(SUBSTITUTE(C2, "(", ""), ")", "") -> IV | C2: =dsa_processed_with_metadata!M588 -> IV
A3: =dsa_processed_with_metadata!J589 -> 78 | B3: =SUBSTITUTE(SUBSTITUTE(C3, "(", ""), ")", "") -> IV | C3: =dsa_processed_with_metadata!M589 -> IV
A4: =dsa_processed_with_metadata!J590 -> 79 | B4: =SUBSTITUTE(SUBSTITUTE(C4, "(", ""), ")", "") -> V | C4: =dsa_processed_with_metadata!M590 -> V
A5: =dsa_processed_with_metadata!J591 -> 79 | B5: =SUBSTITUTE(SUBSTITUTE(C5, "(", ""), ")", "") -> V | C5: =dsa_processed_with_metadata!M591 -> V
A6: =dsa_processed_with_metadata!J592 -> 79 | B6: =SUBSTITUTE(SUBSTITUTE(C6, "(", ""), ")", "") -> V | C6: =dsa_processed_with_metadata!M592 -> V
A7: =dsa_processed_with_metadata!J593 -> 79 | B7: =SUBSTITUTE(SUBSTITUTE(C7, "(", ""), ")", "") -> V | C7: =dsa_processed_with_metadata!M593 -> V | N7: Braak Stage | O7: Average of Age at Death/Bx
A8: =dsa_processed_with_metadata!J594 -> 79 | B8: =SUBSTITUTE(SUBSTITUTE(C8, "(", ""), ")", "") -> V | C8: =dsa_processed_with_metadata!M594 -> V | N8: V | O8: 76.983425
A9: =dsa_processed_with_metadata!J595 -> 79 | B9: =SUBSTITUTE(SUBSTITUTE(C9, "(", ""), ")", "") -> V | C9: =dsa_processed_with_metadata!M595 -> V | N9: IV | O9: 74.823276
A10: =dsa_processed_with_metadata!J596 -> 78 | B10: =SUBSTITUTE(SUBSTITUTE(C10, "(", ""), ")", "") -> V | C10: =dsa_processed_with_metadata!M596 -> V | N10: VI | O10: 74.513393
A11: =dsa_processed_with_metadata!J597 -> 78 | B11: =SUBSTITUTE(SUBSTITUTE(C11, "(", ""), ")", "") -> V | C11: =dsa_processed_with_metadata!M597 -> V | N11: I-II | O11: 72
A12: =dsa_processed_with_metadata!J598 -> 78 | B12: =SUBSTITUTE(SUBSTITUTE(C12, "(", ""), ")", "") -> V | C12: =dsa_processed_with_metadata!M598 -> V | N12: II | O12: 68.304348
A13: =dsa_processed_with_metadata!J599 -> 78 | B13: =SUBSTITUTE(SUBSTITUTE(C13, "(", ""), ")", "") -> V | C13: =dsa_processed_with_metadata!M599 -> V | N13: III | O13: 67.448347
A14: =dsa_processed_with_metadata!J600 -> 78 | B14: =SUBSTITUTE(SUBSTITUTE(C14, "(", ""), ")", "") -> V | C14: =dsa_processed_with_metadata!M600 -> V | N14: I | O14: 58.175
A15: =dsa_processed_with_metadata!J601 -> 77 | B15: =SUBSTITUTE(SUBSTITUTE(C15, "(", ""), ")", "") -> VI | C15: =dsa_processed_with_metadata!M601 -> VI | N15: Grand Total | O15: 71.07837
A16: =dsa_processed_with_metadata!J602 -> 77 | B16: =SUBSTITUTE(SUBSTITUTE(C16, "(", ""), ")", "") -> VI | C16: =dsa_processed_with_metadata!M602 -> VI
A17: =dsa_processed_with_metadata!J603 -> 77 | B17: =SUBSTITUTE(SUBSTITUTE(C17, "(", ""), ")", "") -> VI | C17: =dsa_processed_with_metadata!M603 -> VI
A18: =dsa_processed_with_metadata!J604 -> 77 | B18: =SUBSTITUTE(SUBSTITUTE(C18, "(", ""), ")", "") -> VI | C18: =dsa_processed_with_metadata!M604 -> VI
A19: =dsa_processed_with_metadata!J605 -> 77 | B19: =SUBSTITUTE(SUBSTITUTE(C19, "(", ""), ")", "") -> VI | C19: =dsa_processed_with_metadata!M605 -> VI
A20: =dsa_processed_with_metadata!J606 -> 83 | B20: =SUBSTITUTE(SUBSTITUTE(C20, "(", ""), ")", "") -> V | C20: =dsa_processed_with_metadata!M606 -> V
A21: =dsa_processed_with_metadata!J607 -> 83 | B21: =SUBSTITUTE(SUBSTITUTE(C21, "(", ""), ")", "") -> V | C21: =dsa_processed_with_metadata!M607 -> V
A22: =dsa_processed_with_metadata!J608 -> 83 | B22: =SUBSTITUTE(SUBSTITUTE(C22, "(", ""), ")", "") -> V | C22: =dsa_processed_with_metadata!M608 -> V
A23: =dsa_processed_with_metadata!J609 -> 83 | B23: =SUBSTITUTE(SUBSTITUTE(C23, "(", ""), ")", "") -> V | C23: =dsa_processed_with_metadata!M609 -> V
A24: =dsa_processed_with_metadata!J610 -> 83 | B24: =SUBSTITUTE(SUBSTITUTE(C24, "(", ""), ")", "") -> V | C24: =dsa_processed_with_metadata!M610 -> V
A25: =dsa_processed_with_metadata!J611 -> 83 | B25: =SUBSTITUTE(SUBSTITUTE(C25, "(", ""), ")", "") -> V | C25: =dsa_processed_with_metadata!M611 -> V
A26: =dsa_processed_with_metadata!J612 -> 94 | B26: =SUBSTITUTE(SUBSTITUTE(C26, "(", ""), ")", "") -> V | C26: =dsa_processed_with_metadata!M612 -> V
A27: =dsa_processed_with_metadata!J613 -> 94 | B27: =SUBSTITUTE(SUBSTITUTE(C27, "(", ""), ")", "") -> V | C27: =dsa_processed_with_metadata!M613 -> V
A28: =dsa_processed_with_metadata!J534 -> 72 | B28: =SUBSTITUTE(SUBSTITUTE(C28, "(", ""), ")", "") -> VI | C28: =dsa_processed_with_metadata!M534 -> VI
A29: =dsa_processed_with_metadata!J535 -> 72 | B29: =SUBSTITUTE(SUBSTITUTE(C29, "(", ""), ")", "") -> VI | C29: =dsa_processed_with_metadata!M535 -> VI
A30: =dsa_processed_with_metadata!J536 -> 72 | B30: =SUBSTITUTE(SUBSTITUTE(C30, "(", ""), ")", "") -> VI | C30: =dsa_processed_with_metadata!M536 -> VI
A31: =dsa_processed_with_metadata!J537 -> 72 | B31: =SUBSTITUTE(SUBSTITUTE(C31, "(", ""), ")", "") -> VI | C31: =dsa_processed_with_metadata!M537 -> VI
A32: =dsa_processed_with_metadata!J538 -> 72 | B32: =SUBSTITUTE(SUBSTITUTE(C32, "(", ""), ")", "") -> VI | C32: =dsa_processed_with_metadata!M538 -> VI
A33: =dsa_processed_with_metadata!J1041 -> 54 | B33: =SUBSTITUTE(SUBSTITUTE(C33, "(", ""), ")", "") -> VI | C33: =dsa_processed_with_metadata!M1041 -> VI
A34: =dsa_processed_with_metadata!J1042 -> 54 | B34: =SUBSTITUTE(SUBSTITUTE(C34, "(", ""), ")", "") -> VI | C34: =dsa_processed_with_metadata!M1042 -> VI
A35: =dsa_processed_with_metadata!J1043 -> 63 | B35: =SUBSTITUTE(SUBSTITUTE(C35, "(", ""), ")", "") -> VI | C35: =dsa_processed_with_metadata!M1043 -> VI
A36: =dsa_processed_with_metadata!J1044 -> 63 | B36: =SUBSTITUTE(SUBSTITUTE(C36, "(", ""), ")", "") -> VI | C36: =dsa_processed_with_metadata!M1044 -> VI
A37: =dsa_processed_with_metadata!J1045 -> 63 | B37: =SUBSTITUTE(SUBSTITUTE(C37, "(", ""), ")", "") -> VI | C37: =dsa_processed_with_metadata!M1045 -> VI
A38: =dsa_processed_with_metadata!J1046 -> 63 | B38: =SUBSTITUTE(SUBSTITUTE(C38, "(", ""), ")", "") -> VI | C38: =dsa_processed_with_metadata!M1046 -> VI
A39: =dsa_processed_with_metadata!J1047 -> 63 | B39: =SUBSTITUTE(SUBSTITUTE(C39, "(", ""), ")", "") -> VI | C39: =dsa_processed_with_metadata!M1047 -> VI
A40: =dsa_processed_with_metadata!J1048 -> 63 | B40: =SUBSTITUTE(SUBSTITUTE(C40, "(", ""), ")", "") -> VI | C40: =dsa_processed_with_metadata!M1048 -> VI
...

Sheet Sheet2
A2: Brain Region ID | B2: Count of Brain Region ID
A3: 1 | B3: 259
A4: 4 | B4: 256
A5: 3 | B5: 251
A6: 2 | B6: 249
A7: 19 | B7: 180
A8: 18 | B8: 172
A9: 20 | B9: 149
A10: 1A | B10: 117
A11: 17 | B11: 113
A12: 5 | B12: 107
A13: 1B | B13: 107
A14: 16 | B14: 101
A15: 6 | B15: 99
A16: 11 | B16: 99
A17: 15 | B17: 99
A18: 10 | B18: 99
A19: 7 | B19: 96
A20: 8 | B20: 94
A21: 12 | B21: 93
A22: 13 | B22: 93
A23: 14 | B23: 92
A24: 1C | B24: 92
A25: 9 | B25: 91
A26: 1D | B26: 81
A27: 21 | B27: 68
A28: control | B28: 60
A29: 1S | B29: 48
A30: 1Q | B30: 48
A31: 1R | B31: 46
A32: 1P | B32: 40
A33: 22 | B33: 40
A34: 1E | B34: 38
A35: 1G | B35: 36
A36: 1H | B36: 36
A37: 1O | B37: 33
A38: 1I | B38: 32
A39: 1J | B39: 30
A40: 1F | B40: 29
A41: 1T | B41: 29
...

Sheet Sheet3
A2: Clin Dx | B2: Count of Clin Dx
A3: ALS | B3: 406
A4: AD | B4: 347
A5: FTD | B5: 213
A6: ALS; stem cell transplant | B6: 144
A7: ALS (ASO TRIAL) | B7: 96
A8: DLB | B8: 55
A9: ALS+FTD | B9: 51
A10: PDD | B10: 45
A11: FTD+ALS | B11: 44
A12: FTD; ALS | B12: 41
A13: EOAD | B13: 36
A14: PD | B14: 28
... A81: Grand Total | B81: 2205

Sheet Tar
A1: Sex | B1: Age at Onset | I1: Race | J1: Primary Neuropathologic Diagnosis | L1: Race | M1: Count of Race
A2: m | B2: 53 | D2: Sex | E2: Count of Sex | I2: w | J2: AD | L2: w | M2: 1969
A3: m | B3: 53 | D3: m | E3: 1197 | I3: w | J3: AD | L3: b | M3: 155
A4: m | B4: 53 | D4: f | E4: 895 | I4: w | J4: AD | L4: hw | M4: 49
A5: m | B5: 53 | D5: Grand Total | E5: 2092 | I5: w | J5: AD | L5: h | M5: 40 | N5: ￼
A6: m | B6: 53 | I6: w | J6: AD | L6: Grand Total | M6: 2213
A7: m | B7: 53 | D7: Sex | E7: Average of Age at Onset | I7: w | J7: AD
A8: m | B8: 53 | D8: f | E8: 62.242458 | I8: w | J8: AD
A9: m | B9: 53 | D9: m | E9: 59.081376 | I9: w | J9: AD | L9: Count of Primary Neuropathologic Diagnosis | M9: Race
A10: f | B10: 64 | I10: w | J10: AD | L10: Primary Neuropathologic Diagnosis | M10: w | N10: b | O10: hw | P10: h | Q10: Grand Total
A11: f | B11: 64 | I11: w | J11: AD | L11: AD | M11: 604 | N11: 116 | O11: 7 | Q11: 727
A12: f | B12: 64 | I12: w | J12: AD | L12: ALS (C9 expansion) | M12: 327 | Q12: 327
A13: f | B13: 64 | I13: w | J13: AD | L13: ALS | M13: 210 | Q13: 210
A14: f | B14: 81 | I14: b | J14: AD | L14: LBD-neocortical | M14: 117 | N14: 8 | Q14: 125
A15: f | B15: 81 | I15: b | J15: AD | L15: FTLD-TDP (C9 expansion) | M15: 102 | Q15: 102
A16: f | B16: 81 | I16: b | J16: AD | L16: FTLD-TDP | M16: 57 | N16: 14 | Q16: 71
A17: f | B17: 81 | I17: b | J17: AD | L17: ALS (stem cell pt) | M17: 69 | Q17: 69
A18: f | B18: 81 | I18: b | J18: AD | L18: FTLD-tau (CBD) | M18: 44 | Q18: 44
A19: f | B19: 81 | I19: b | J19: AD | L19: MCI | M19: 41 | Q19: 41
A20: f | B20: 81 | I20: b | J20: AD | L20: ALS (stem cell patient) | P20: 40 | Q20: 40
A21: m | B21: 73 | I21: w | J21: AD | L21: FTLD-tau (Pick's) | M21: 21 | O21: 18 | Q21: 39
A22: m | B22: 73 | I22: w | J22: AD | L22: FTLD-TDP (GRN mutation) | M22: 36 | Q22: 36
A23: m | B23: 73 | I23: w | J23: AD | L23: Glioblastoma-grade IV | M23: 35 | Q23: 35
A24: m | B24: 73 | I24: w | J24: AD | L24: Control | M24: 18 | N24: 17 | Q24: 35
A25: m | B25: 73 | I25: w | J25: AD | L25: FTLD-tau (unclassified) | M25: 29 | Q25: 29
A26: m | B26: 73 | I26: w | J26: AD | L26: ALS (FUS mutation) | O26: 24 | Q26: 24
A27: f | B27: 71 | I27: w | J27: AD | L27: FTLD-TDP (likely C9 expansion) | M27: 22 | Q27: 22
A28: f | B28: 71 | I28: w | J28: AD | L28: FTDP-17 (presumed) | M28: 22 | Q28: 22
A29: f | B29: 71 | I29: w | J29: AD | L29: FTDP-17 (G389R) | M29: 20 | Q29: 20
A30: f | B30: 71 | I30: w | J30: AD | L30: FTDP-17 (P301L) | M30: 19 | Q30: 19
A31: f | B31: 71 | I31: w | J31: AD | L31: FTLD-TDP (familial;negative for MAPT, GRN and C9) | M31: 19 | Q31: 19
A32: f | B32: 71 | I32: w | J32: AD | L32: LBD-limbic | M32: 15 | Q32: 15
A33: f | B33: 71 | I33: w | J33: AD | L33: Control/asymptomatic AD | M33: 14 | Q33: 14
A34: m | B34: 59 | I34: w | J34: AD | L34: AD-probable | M34: 14 | Q34: 14
A35: m | B35: 59 | I35: w | J35: AD | L35: FTLD-tau (PSP,with features of CBD) | M35: 13 | Q35: 13
A36: m | B36: 59 | I36: w | J36: AD | L36: Hp sclerosis | M36: 8 | Q36: 8
A37: m | B37: 59 | I37: w | J37: AD | L37: MCI - ADNI | M37: 8 | Q37: 8
A38: m | B38: 59 | I38: w | J38: AD | L38: FTLD-tau (PSP) | M38: 7 | Q38: 7
... A52: f | B52: 82 | I52: w | J52: AD | L52: Hereditary Diffuse Leukoencephalopathy with Axonal Spheroids | M52: 1 | Q52: 1
A53: f | B53: 82 | I53: w | J53: AD | L53: Grand Total | M53: 1969 | N53: 155 | O53: 49 | P53: 40 | Q53: 2213
...

Sheet POI
A1: # | B1: Patients | C1: Primary neuropathologic dx | D1: Year | E1: LATE Stage
A2: 1 | B2: E23-149 | C2: ALS | D2: 2023
A3: 2 | B3: E23-52 | C3: ALS | D3: 2023
A4: 3 | B4: E20-131 | C4: ALS | D4: 2020
A5: 4 | B5: E20-95 | C5: ALS | D5: 2020
A6: 5 | B6: E19-27 | C6: ALS | D6: 2019
A7: 6 | B7: E17-12 | C7: ALS | D7: 2017
A8: 7 | B8: E17-129 | C8: ALS | D8: 2017
A9: 8 | B9: E15-61 | C9: ALS | D9: 2015
A10: 9 | B10: E22-48 | C10: Control | D10: 2022
A11: 10 | B11: E16-45 | C11: Control | D11: 2016
A12: 11 | B12: E20-18 | C12: Control | D12: 2020
A13: 12 | B13: E15-106 | C13: Control | D13: 2015
... A24: 23 | B24: E19-139 | C24: FTLD-TDP | D24: 2019
B25: E19-131 | C25: LATE-NC (Stage 1) | D25: 2019 | E25: 1
B26: E20-55 | C26: LATE-NC (Stage 1) | D26: 2020 | E26: 1
B27: E24-44 | C27: LATE-NC (Stage 1) | D27: 2024 | E27: 1
B28: E19-101 | C28: LATE-NC (Stage 2) | D28: 2019 | E28: 2
B29: E24-12 | C29: LATE-NC (Stage 2) | D29: 2024 | E29: 2
B30: E23-79 | C30: LATE-NC (Stage 2) | D30: 2023 | E30: 2
B31: E14-104 | C31: LATE-NC (Stage 3) | D31: 2014 | E31: 3
B32: E20-138 | C32: LATE-NC (Stage 3) | D32: 2020 | E32: 3
B33: E24-91 | C33: LATE-NC (Stage 3) | D33: 2024 | E33: 3

Sheet E21-95_pTDP_1

Sheet E21-95_pTDP_3
A1: Cluster # | B1: Bad | C1: Debris | D1: TDP +? | E1: cNCI (compact neuronal cytoplasmic inclusions) | F1: dNCI (diffuse granular morphology of neuronal cytoplasmic inclusions) | G1: sDN (short dystrophic neurites) | H1: lDN (long dystrophic neurites) | I1: NII (lentiform neuronal intranuclear inclusions) | J1: ThD (delicate small TDP-43-ir threads) | K1: Revisit ? | L1: Column1
A2: 1
A3: 2
A4: 3
A5: 4
A6: 5
A7: 6
A8: 7
A9: 8
A10: 9
A11: 10
A12: 11
A13: 12
... A187: 186
A188: 187 | B188: 0 | C188: 1
A189: 188
A190: 189
A191: 190
A192: 191
A193: 192
A194: 193
A195: 194
A196: 195
A197: 196
A198: 197
A199: 198
A200: 199
... A1005: 1004
A1006: 1005 | B1006: 0 | C1006: 0 | D1006: 1 | E1006: 1 | F1006: 0 | G1006: 0 | H1006: 0 | I1006: 0 | J1006: 0
A1007: 1006
A1008: 1007
A1009: 1008
A1010: 1009
A1011: 1010
A1012: 1011
A1013: 1012
A1014: 1013
A1015: 1014
A1016: 1015
A1017: 1016
...
